Traceback (most recent call last):
  File "/home/ubuntu/workspace/Python_Automate_examples/Debug.py", line 23, in <module>
    raise Exception('This is the error message.')
Exception: This is the error message.
Traceback (most recent call last):
  File "/home/ubuntu/workspace/Python_Automate_examples/Debug.py", line 23, in <module>
    raise Exception('This is the error message.')
Exception: This is the error message.
Traceback (most recent call last):
  File "/home/ubuntu/workspace/Python_Automate_examples/Debug.py", line 19, in <module>
    raise Exception('This is the error message.')
Exception: This is the error message.
Traceback (most recent call last):
  File "/home/ubuntu/workspace/Python_Automate_examples/Debug.py", line 19, in <module>
    raise Exception('This is the error message.')
Exception: This is the error message.
Traceback (most recent call last):
  File "/home/ubuntu/workspace/Python_Automate_examples/Debug.py", line 19, in <module>
    raise Exception('This is the error message.')
Exception: This is the error message.
Traceback (most recent call last):
  File "/home/ubuntu/workspace/Python_Automate_examples/Debug.py", line 19, in <module>
    raise Exception('This is the error message.')
Exception: This is the error message.
Traceback (most recent call last):
  File "/home/ubuntu/workspace/Python_Automate_examples/Debug.py", line 19, in <module>
    raise Exception('This is the error message.')
Exception: This is the error message.
